Workbook

Sheet 목록 최종정리
A1: carid | B1: 차량번호 | C1: 색상 | D1: 제조사 | E1: 세부모델 | F1: 트림 | G1: 세부트림 | H1: 연식 | I1: 유종 | J1: 차형 | K1: 판매금액 | L1: 주행거리 | M1: 최초등록년월 | N1: 판매자ID | O1: 판매자명 | P1: 판매자 세부정보(사업자등록번호, 조합, 전화번호, 매매사원번호등) | Q1: 성능점검등록방식 | R1: 성능점검지 이미지 | S1: 렌트이력 | V1: 차대번호 | W1: 단순수리 | X1: 사고이력 | Y1: 유상옵션 | Z1: 기본옵션
A2: 41356587 | B2: =VLOOKUP(A2,vehicle_detail!$A$2:$DK$101,111,FALSE) -> 157더9839 | C2: =VLOOKUP(A2,vehicle_detail!$A$2:$DK$101,101,FALSE) -> 쥐색 | D2: =VLOOKUP(A2,list_100!$B$2:$P$101,9,FALSE) -> 현대 | E2: =VLOOKUP(A2,list_100!$B$2:$P$101,11,FALSE) -> 아반떼 (CN7) | F2: =VLOOKUP(A2,list_100!$B$2:$P$101,2,FALSE) -> 1.6 | G2: =VLOOKUP(A2,list_100!$B$2:$P$101,3,FALSE) -> 모던 | H2: =VLOOKUP(A2,list_100!$B$2:$P$101,6,FALSE) -> 2021 | I2: =VLOOKUP(A2,list_100!$B$2:$P$101,7,FALSE) -> 가솔린 | J2: =VLOOKUP(A2,vehicle_detail!$A$2:$DK$101,100,FALSE) -> 준중형차 | K2: =VLOOKUP(A2,list_100!$B$2:$P$101,15,FALSE) -> 1219 | L2: =VLOOKUP(A2,list_100!$B$2:$P$101,10,FALSE) -> 154242 | M2: =VLOOKUP(A2,list_100!$B$2:$V$101,21,FALSE) -> 202010 | N2: =VLOOKUP(A2,seller_user!$A$2:$Y$101,2,FALSE) -> dnfltnghk92 | O2: =VLOOKUP(A2,seller_user!$A$2:$Y$101,25,FALSE) -> 신윤석 | P2: =VLOOKUP(A2,seller_user!$A$2:$Y$101,3,FALSE) -> [{"companyType": "FIRM", "companyName": "카메이트", "brn": "438-18-00082", "associationCd": 28, "associationName": "경기 자동차매매사업조합", "associationPhoneNumber": "031-242-8940", "certificatedEmployeeNumber": "GC21-05732", "address": {"zipcode": "16602 ", "location": null, "sido": "경기", "sigungu": "수원시 권선구", "eupmyeondong": null, "eupmyeondongEtc": null, "address": "경기 수원시 권선구 권선로 308", "buildingCd": "4111312800100140134000001"}, "contacts": null, "used": true}] | Q2: =VLOOKUP(A2,inspection_detail_raw!A2:BK101,4,FALSE) -> ["IMAGE"] | R2: =IFERROR("https://ci.encar.com"&VLOOKUP(A2,'성능점검 이미지정보'!A:E,2,FALSE),"") -> https://ci.encar.com/carsdata/cars/inspection/41356587_photoPerform1.jpg | S2: =IFERROR(VLOOKUP(TEXT(A2,"0"), inspection_detail_raw!A:BK, 50, FALSE), "알수없음") -> 0 | T2: =IFERROR(VLOOKUP(TEXT(A2,"0"), inspection_detail_raw!A:BK, 51, FALSE), "알수없음") -> 0 | U2: =IFERROR(VLOOKUP(TEXT(A2,"0"), inspection_detail_raw!A:BK, 52, FALSE), "알수없음") -> 0 | V2: =IFERROR(VLOOKUP(TEXT(A2,"0"), inspection_detail_raw!A:BK, 54, FALSE), "알수없음") -> 0 | W2: =IFERROR(VLOOKUP(TEXT(A2,"0"), inspection_detail_raw!A:BK, 57, FALSE), "알수없음") -> TRUE | X2: =IFERROR(VLOOKUP(TEXT(A2,"0"), inspection_detail_raw!A:BK, 59, FALSE), "알수없음") -> [] | Y2: =VLOOKUP(A2,vehicle_detail!$A$2:$DK$101,78,FALSE) -> ["10001", "10008", "10006", "10002"] | Z2: =VLOOKUP(A2,vehicle_detail!$A$2:$DK$101,80,FALSE) -> ["001", "005", "006", "007", "008", "014", "015", "017", "019", "020", "021", "022", "023", "024", "026", "027", "030", "031", "032", "033", "034", "051", "055", "056", "057", "058", "072", "074", "077", "079", "082", "088", "094", "096", "097"]
A3: 41353573 | B3: =VLOOKUP(A3,vehicle_detail!$A$2:$DK$101,111,FALSE) -> 41모5330 | C3: =VLOOKUP(A3,vehicle_detail!$A$2:$DK$101,101,FALSE) -> 쥐색 | D3: =VLOOKUP(A3,list_100!$B$2:$P$101,9,FALSE) -> 현대 | E3: =VLOOKUP(A3,list_100!$B$2:$P$101,11,FALSE) -> 싼타페 더 프라임 | F3: =VLOOKUP(A3,list_100!$B$2:$P$101,2,FALSE) -> 디젤 2.0 2WD | G3: =VLOOKUP(A3,list_100!$B$2:$P$101,3,FALSE) -> 익스클루시브 | H3: =VLOOKUP(A3,list_100!$B$2:$P$101,6,FALSE) -> 2016 | I3: =VLOOKUP(A3,list_100!$B$2:$P$101,7,FALSE) -> 디젤 | J3: =VLOOKUP(A3,vehicle_detail!$A$2:$DK$101,100,FALSE) -> SUV | K3: =VLOOKUP(A3,list_100!$B$2:$P$101,15,FALSE) -> 1039 | L3: =VLOOKUP(A3,list_100!$B$2:$P$101,10,FALSE) -> 179987 | M3: =VLOOKUP(A3,list_100!$B$2:$V$101,21,FALSE) -> 201506 | N3: =VLOOKUP(A3,seller_user!$A$2:$Y$101,2,FALSE) -> dnfltnghk92 | O3: =VLOOKUP(A3,seller_user!$A$2:$Y$101,25,FALSE) -> 신윤석 | P3: =VLOOKUP(A3,seller_user!$A$2:$Y$101,3,FALSE) -> [{"companyType": "FIRM", "companyName": "카메이트", "brn": "438-18-00082", "associationCd": 28, "associationName": "경기 자동차매매사업조합", "associationPhoneNumber": "031-242-8940", "certificatedEmployeeNumber": "GC21-05732", "address": {"zipcode": "16602 ", "location": null, "sido": "경기", "sigungu": "수원시 권선구", "eupmyeondong": null, "eupmyeondongEtc": null, "address": "경기 수원시 권선구 권선로 308", "buildingCd": "4111312800100140134000001"}, "contacts": null, "used": true}] | Q3: =VLOOKUP(A3,inspection_detail_raw!A3:BK102,4,FALSE) -> ["IMAGE"] | R3: =IFERROR("https://ci.encar.com"&VLOOKUP(A3,'성능점검 이미지정보'!A:E,2,FALSE),"") -> https://ci.encar.com/carsdata/cars/inspection/41353573_photoPerform1.jpg | S3: =VLOOKUP(A3,inspection_detail_raw!A3:BK102,50,FALSE) -> 0 | T3: =IFERROR(VLOOKUP(TEXT(A3,"0"), inspection_detail_raw!A:BK, 51, FALSE), "알수없음") -> 0 | U3: =IFERROR(VLOOKUP(TEXT(A3,"0"), inspection_detail_raw!A:BK, 52, FALSE), "알수없음") -> 0 | V3: =IFERROR(VLOOKUP(TEXT(A3,"0"), inspection_detail_raw!A:BK, 54, FALSE), "알수없음") -> 0 | W3: =IFERROR(VLOOKUP(TEXT(A3,"0"), inspection_detail_raw!A:BK, 57, FALSE), "알수없음") -> FALSE | X3: =IFERROR(VLOOKUP(TEXT(A3,"0"), inspection_detail_raw!A:BK, 59, FALSE), "알수없음") -> [] | Y3: =VLOOKUP(A3,vehicle_detail!$A$2:$DK$101,78,FALSE) -> ["1124", "1126", "1094"] | Z3: =VLOOKUP(A3,vehicle_detail!$A$2:$DK$101,80,FALSE) -> ["001", "003", "005", "006", "007", "008", "010", "014", "015", "017", "019", "020", "021", "022", "023", "024", "026", "027", "029", "030", "031", "032", "033", "034", "035", "051", "055", "056", "057", "058", "062", "063", "068", "071", "072", "074", "077", "082", "085", "092", "094", "096", "097"]
A4: 41403456 | B4: =VLOOKUP(A4,vehicle_detail!$A$2:$DK$101,111,FALSE) -> 57모1896 | C4: =VLOOKUP(A4,vehicle_detail!$A$2:$DK$101,101,FALSE) -> 흰색 | D4: =VLOOKUP(A4,list_100!$B$2:$P$101,9,FALSE) -> 현대 | E4: =VLOOKUP(A4,list_100!$B$2:$P$101,11,FALSE) -> 그랜저 HG | F4: =VLOOKUP(A4,list_100!$B$2:$P$101,2,FALSE) -> HG240 모던 | G4: =VLOOKUP(A4,list_100!$B$2:$P$101,3,FALSE) -> 0 | H4: =VLOOKUP(A4,list_100!$B$2:$P$101,6,FALSE) -> 2014 | I4: =VLOOKUP(A4,list_100!$B$2:$P$101,7,FALSE) -> 가솔린 | J4: =VLOOKUP(A4,vehicle_detail!$A$2:$DK$101,100,FALSE) -> 대형차 | K4: =VLOOKUP(A4,list_100!$B$2:$P$101,15,FALSE) -> 459 | L4: =VLOOKUP(A4,list_100!$B$2:$P$101,10,FALSE) -> 196565 | M4: =VLOOKUP(A4,list_100!$B$2:$V$101,21,FALSE) -> 201306 | N4: =VLOOKUP(A4,seller_user!$A$2:$Y$101,2,FALSE) -> dnfltnghk92 | O4: =VLOOKUP(A4,seller_user!$A$2:$Y$101,25,FALSE) -> 신윤석 | P4: =VLOOKUP(A4,seller_user!$A$2:$Y$101,3,FALSE) -> [{"companyType": "FIRM", "companyName": "카메이트", "brn": "438-18-00082", "associationCd": 28, "associationName": "경기 자동차매매사업조합", "associationPhoneNumber": "031-242-8940", "certificatedEmployeeNumber": "GC21-05732", "address": {"zipcode": "16602 ", "location": null, "sido": "경기", "sigungu": "수원시 권선구", "eupmyeondong": null, "eupmyeondongEtc": null, "address": "경기 수원시 권선구 권선로 308", "buildingCd": "4111312800100140134000001"}, "contacts": null, "used": true}] | Q4: =VLOOKUP(A4,inspection_detail_raw!A4:BK103,4,FALSE) -> ["IMAGE"] | R4: =IFERROR("https://ci.encar.com"&VLOOKUP(A4,'성능점검 이미지정보'!A:E,2,FALSE),"") -> https://ci.encar.com/carsdata/cars/inspection/41403456_photoPerform1.jpg | S4: =VLOOKUP(A4,inspection_detail_raw!A4:BK103,50,FALSE) -> 0 | T4: =IFERROR(VLOOKUP(TEXT(A4,"0"), inspection_detail_raw!A:BK, 51, FALSE), "알수없음") -> 0 | U4: =IFERROR(VLOOKUP(TEXT(A4,"0"), inspection_detail_raw!A:BK, 52, FALSE), "알수없음") -> 0 | V4: =IFERROR(VLOOKUP(TEXT(A4,"0"), inspection_detail_raw!A:BK, 54, FALSE), "알수없음") -> 0 | W4: =IFERROR(VLOOKUP(TEXT(A4,"0"), inspection_detail_raw!A:BK, 57, FALSE), "알수없음") -> FALSE | X4: =IFERROR(VLOOKUP(TEXT(A4,"0"), inspection_detail_raw!A:BK, 59, FALSE), "알수없음") -> [] | Y4: =VLOOKUP(A4,vehicle_detail!$A$2:$DK$101,78,FALSE) -> ["1128", "1125", "1129", "1109"] | Z4: =VLOOKUP(A4,vehicle_detail!$A$2:$DK$101,80,FALSE) -> ["001", "003", "005", "006", "007", "008", "010", "014", "015", "017", "019", "020", "021", "022", "023", "024", "026", "027", "030", "031", "032", "033", "034", "035", "051", "055", "056", "057", "058", "063", "068", "071", "072", "074", "077", "082", "085", "094", "096", "097"]
A5: 41390361 | B5: =VLOOKUP(A5,vehicle_detail!$A$2:$DK$101,111,FALSE) -> 166어8176 | C5: =VLOOKUP(A5,vehicle_detail!$A$2:$DK$101,101,FALSE) -> 흰색 | D5: =VLOOKUP(A5,list_100!$B$2:$P$101,9,FALSE) -> 현대 | E5: =VLOOKUP(A5,list_100!$B$2:$P$101,11,FALSE) -> 더 뉴 아반떼 AD | F5: =VLOOKUP(A5,list_100!$B$2:$P$101,2,FALSE) -> 1.6 | G5: =VLOOKUP(A5,list_100!$B$2:$P$101,3,FALSE) -> 스마트 | H5: =VLOOKUP(A5,list_100!$B$2:$P$101,6,FALSE) -> 2019 | I5: =VLOOKUP(A5,list_100!$B$2:$P$101,7,FALSE) -> 가솔린 | J5: =VLOOKUP(A5,vehicle_detail!$A$2:$DK$101,100,FALSE) -> 준중형차 | K5: =VLOOKUP(A5,list_100!$B$2:$P$101,15,FALSE) -> 999 | L5: =VLOOKUP(A5,list_100!$B$2:$P$101,10,FALSE) -> 94655 | M5: =VLOOKUP(A5,list_100!$B$2:$V$101,21,FALSE) -> 201810 | N5: =VLOOKUP(A5,seller_user!$A$2:$Y$101,2,FALSE) -> dnfltnghk92 | O5: =VLOOKUP(A5,seller_user!$A$2:$Y$101,25,FALSE) -> 신윤석 | P5: =VLOOKUP(A5,seller_user!$A$2:$Y$101,3,FALSE) -> [{"companyType": "FIRM", "companyName": "카메이트", "brn": "438-18-00082", "associationCd": 28, "associationName": "경기 자동차매매사업조합", "associationPhoneNumber": "031-242-8940", "certificatedEmployeeNumber": "GC21-05732", "address": {"zipcode": "16602 ", "location": null, "sido": "경기", "sigungu": "수원시 권선구", "eupmyeondong": null, "eupmyeondongEtc": null, "address": "경기 수원시 권선구 권선로 308", "buildingCd": "4111312800100140134000001"}, "contacts": null, "used": true}] | Q5: =VLOOKUP(A5,inspection_detail_raw!A5:BK104,4,FALSE) -> ["IMAGE"] | R5: =IFERROR("https://ci.encar.com"&VLOOKUP(A5,'성능점검 이미지정보'!A:E,2,FALSE),"") -> https://ci.encar.com/carsdata/cars/inspection/41390361_photoPerform1.jpg | S5: =VLOOKUP(A5,inspection_detail_raw!A5:BK104,50,FALSE) -> 0 | T5: =IFERROR(VLOOKUP(TEXT(A5,"0"), inspection_detail_raw!A:BK, 51, FALSE), "알수없음") -> 0 | U5: =IFERROR(VLOOKUP(TEXT(A5,"0"), inspection_detail_raw!A:BK, 52, FALSE), "알수없음") -> 0 | V5: =IFERROR(VLOOKUP(TEXT(A5,"0"), inspection_detail_raw!A:BK, 54, FALSE), "알수없음") -> 0 | W5: =IFERROR(VLOOKUP(TEXT(A5,"0"), inspection_detail_raw!A:BK, 57, FALSE), "알수없음") -> TRUE | X5: =IFERROR(VLOOKUP(TEXT(A5,"0"), inspection_detail_raw!A:BK, 59, FALSE), "알수없음") -> [] | Y5: =VLOOKUP(A5,vehicle_detail!$A$2:$DK$101,78,FALSE) -> ["1143", "1144", "1142"] | Z5: =VLOOKUP(A5,vehicle_detail!$A$2:$DK$101,80,FALSE) -> ["001", "005", "006", "007", "008", "014", "015", "017", "019", "020", "022", "023", "024", "026", "027", "030", "031", "032", "033", "055", "056", "057", "058", "071", "072", "074", "075", "082", "088", "096", "097"]
A6: 41403526 | B6: =VLOOKUP(A6,vehicle_detail!$A$2:$DK$101,111,FALSE) -> 46로4665 | C6: =VLOOKUP(A6,vehicle_detail!$A$2:$DK$101,101,FALSE) -> 흰색 | D6: =VLOOKUP(A6,list_100!$B$2:$P$101,9,FALSE) -> 현대 | E6: =VLOOKUP(A6,list_100!$B$2:$P$101,11,FALSE) -> i30(신형) | F6: =VLOOKUP(A6,list_100!$B$2:$P$101,2,FALSE) -> 디젤 1.6 VGT 익스트림 | G6: =VLOOKUP(A6,list_100!$B$2:$P$101,3,FALSE) -> 0 | H6: =VLOOKUP(A6,list_100!$B$2:$P$101,6,FALSE) -> 2012 | I6: =VLOOKUP(A6,list_100!$B$2:$P$101,7,FALSE) -> 디젤 | J6: =VLOOKUP(A6,vehicle_detail!$A$2:$DK$101,100,FALSE) -> 준중형차 | K6: =VLOOKUP(A6,list_100!$B$2:$P$101,15,FALSE) -> 549 | L6: =VLOOKUP(A6,list_100!$B$2:$P$101,10,FALSE) -> 165201 | M6: =VLOOKUP(A6,list_100!$B$2:$V$101,21,FALSE) -> 201212 | N6: =VLOOKUP(A6,seller_user!$A$2:$Y$101,2,FALSE) -> dnfltnghk92 | O6: =VLOOKUP(A6,seller_user!$A$2:$Y$101,25,FALSE) -> 신윤석 | P6: =VLOOKUP(A6,seller_user!$A$2:$Y$101,3,FALSE) -> [{"companyType": "FIRM", "companyName": "카메이트", "brn": "438-18-00082", "associationCd": 28, "associationName": "경기 자동차매매사업조합", "associationPhoneNumber": "031-242-8940", "certificatedEmployeeNumber": "GC21-05732", "address": {"zipcode": "16602 ", "location": null, "sido": "경기", "sigungu": "수원시 권선구", "eupmyeondong": null, "eupmyeondongEtc": null, "address": "경기 수원시 권선구 권선로 308", "buildingCd": "4111312800100140134000001"}, "contacts": null, "used": true}] | Q6: =VLOOKUP(A6,inspection_detail_raw!A6:BK105,4,FALSE) -> ["IMAGE"] | R6: =IFERROR("https://ci.encar.com"&VLOOKUP(A6,'성능점검 이미지정보'!A:E,2,FALSE),"") -> https://ci.encar.com/carsdata/cars/inspection/41403526_photoPerform1.jpg | S6: =VLOOKUP(A6,inspection_detail_raw!A6:BK105,50,FALSE) -> 0 | T6: =IFERROR(VLOOKUP(TEXT(A6,"0"), inspection_detail_raw!A:BK, 51, FALSE), "알수없음") -> 0 | U6: =IFERROR(VLOOKUP(TEXT(A6,"0"), inspection_detail_raw!A:BK, 52, FALSE), "알수없음") -> 0 | V6: =IFERROR(VLOOKUP(TEXT(A6,"0"), inspection_detail_raw!A:BK, 54, FALSE), "알수없음") -> 0 | W6: =IFERROR(VLOOKUP(TEXT(A6,"0"), inspection_detail_raw!A:BK, 57, FALSE), "알수없음") -> FALSE | X6: =IFERROR(VLOOKUP(TEXT(A6,"0"), inspection_detail_raw!A:BK, 59, FALSE), "알수없음") -> [] | Y6: =VLOOKUP(A6,vehicle_detail!$A$2:$DK$101,78,FALSE) -> ["1005", "1007", "1004", "1010"] | Z6: =VLOOKUP(A6,vehicle_detail!$A$2:$DK$101,80,FALSE) -> ["001", "003", "005", "006", "007", "008", "010", "014", "015", "017", "019", "020", "021", "022", "023", "024", "026", "027", "029", "030", "031", "032", "055", "056", "057", "058", "071", "072", "074", "094", "096", "097"]
A7: 40279299 | B7: =VLOOKUP(A7,vehicle_detail!$A$2:$DK$101,111,FALSE) -> 69부0622 | C7: =VLOOKUP(A7,vehicle_detail!$A$2:$DK$101,101,FALSE) -> 은색 | D7: =VLOOKUP(A7,list_100!$B$2:$P$101,9,FALSE) -> 현대 | E7: =VLOOKUP(A7,list_100!$B$2:$P$101,11,FALSE) -> LF 쏘나타 | F7: =VLOOKUP(A7,list_100!$B$2:$P$101,2,FALSE) -> 2.0 스마트 | G7: =VLOOKUP(A7,list_100!$B$2:$P$101,3,FALSE) -> 스페셜 | H7: =VLOOKUP(A7,list_100!$B$2:$P$101,6,FALSE) -> 2016 | I7: =VLOOKUP(A7,list_100!$B$2:$P$101,7,FALSE) -> 가솔린 | J7: =VLOOKUP(A7,vehicle_detail!$A$2:$DK$101,100,FALSE) -> 중형차 | K7: =VLOOKUP(A7,list_100!$B$2:$P$101,15,FALSE) -> 669 | L7: =VLOOKUP(A7,list_100!$B$2:$P$101,10,FALSE) -> 182436 | M7: =VLOOKUP(A7,list_100!$B$2:$V$101,21,FALSE) -> 201609 | N7: =VLOOKUP(A7,seller_user!$A$2:$Y$101,2,FALSE) -> dnfltnghk92 | O7: =VLOOKUP(A7,seller_user!$A$2:$Y$101,25,FALSE) -> 신윤석 | P7: =VLOOKUP(A7,seller_user!$A$2:$Y$101,3,FALSE) -> [{"companyType": "FIRM", "companyName": "카메이트", "brn": "438-18-00082", "associationCd": 28, "associationName": "경기 자동차매매사업조합", "associationPhoneNumber": "031-242-8940", "certificatedEmployeeNumber": "GC21-05732", "address": {"zipcode": "16602 ", "location": null, "sido": "경기", "sigungu": "수원시 권선구", "eupmyeondong": null, "eupmyeondongEtc": null, "address": "경기 수원시 권선구 권선로 308", "buildingCd": "4111312800100140134000001"}, "contacts": null, "used": true}] | Q7: =VLOOKUP(A7,inspection_detail_raw!A7:BK106,4,FALSE) -> ["IMAGE"] | R7: =IFERROR("https://ci.encar.com"&VLOOKUP(A7,'성능점검 이미지정보'!A:E,2,FALSE),"") -> https://ci.encar.com/carsdata/cars/inspection/40279299_photoPerform1.jpg | S7: =VLOOKUP(A7,inspection_detail_raw!A7:BK106,50,FALSE) -> 0 | T7: =IFERROR(VLOOKUP(TEXT(A7,"0"), inspection_detail_raw!A:BK, 51, FALSE), "알수없음") -> 0 | U7: =IFERROR(VLOOKUP(TEXT(A7,"0"), inspection_detail_raw!A:BK, 52, FALSE), "알수없음") -> 0 | V7: =IFERROR(VLOOKUP(TEXT(A7,"0"), inspection_detail_raw!A:BK, 54, FALSE), "알수없음") -> 0 | W7: =IFERROR(VLOOKUP(TEXT(A7,"0"), inspection_detail_raw!A:BK, 57, FALSE), "알수없음") -> TRUE | X7: =IFERROR(VLOOKUP(TEXT(A7,"0"), inspection_detail_raw!A:BK, 59, FALSE), "알수없음") -> [] | Y7: =VLOOKUP(A7,vehicle_detail!$A$2:$DK$101,78,FALSE) -> [] | Z7: =VLOOKUP(A7,vehicle_detail!$A$2:$DK$101,80,FALSE) -> ["001", "003", "005", "006", "007", "008", "014", "015", "017", "019", "020", "021", "022", "023", "024", "026", "027", "030", "031", "032", "033", "034", "035", "055", "056", "057", "058", "068", "071", "072", "074", "077", "082", "086", "094", "096", "097"]
A8: 41017047 | B8: =VLOOKUP(A8,vehicle_detail!$A$2:$DK$101,111,FALSE) -> 87너0218 | C8: =VLOOKUP(A8,vehicle_detail!$A$2:$DK$101,101,FALSE) -> 은색 | D8: =VLOOKUP(A8,list_100!$B$2:$P$101,9,FALSE) -> 현대 | E8: =VLOOKUP(A8,list_100!$B$2:$P$101,11,FALSE) -> 더 뉴 그랜드 스타렉스 | F8: =VLOOKUP(A8,list_100!$B$2:$P$101,2,FALSE) -> 밴 5인승 | G8: =VLOOKUP(A8,list_100!$B$2:$P$101,3,FALSE) -> 스타일 | H8: =VLOOKUP(A8,list_100!$B$2:$P$101,6,FALSE) -> 2021 | I8: =VLOOKUP(A8,list_100!$B$2:$P$101,7,FALSE) -> 디젤 | J8: =VLOOKUP(A8,vehicle_detail!$A$2:$DK$101,100,FALSE) -> 승합차 | K8: =VLOOKUP(A8,list_100!$B$2:$P$101,15,FALSE) -> 1419 | L8: =VLOOKUP(A8,list_100!$B$2:$P$101,10,FALSE) -> 64214 | M8: =VLOOKUP(A8,list_100!$B$2:$V$101,21,FALSE) -> 202010 | N8: =VLOOKUP(A8,seller_user!$A$2:$Y$101,2,FALSE) -> dnfltnghk92 | O8: =VLOOKUP(A8,seller_user!$A$2:$Y$101,25,FALSE) -> 신윤석 | P8: =VLOOKUP(A8,seller_user!$A$2:$Y$101,3,FALSE) -> [{"companyType": "FIRM", "companyName": "카메이트", "brn": "438-18-00082", "associationCd": 28, "associationName": "경기 자동차매매사업조합", "associationPhoneNumber": "031-242-8940", "certificatedEmployeeNumber": "GC21-05732", "address": {"zipcode": "16602 ", "location": null, "sido": "경기", "sigungu": "수원시 권선구", "eupmyeondong": null, "eupmyeondongEtc": null, "address": "경기 수원시 권선구 권선로 308", "buildingCd": "4111312800100140134000001"}, "contacts": null, "used": true}] | Q8: =VLOOKUP(A8,inspection_detail_raw!A8:BK107,4,FALSE) -> ["IMAGE"] | R8: =IFERROR("https://ci.encar.com"&VLOOKUP(A8,'성능점검 이미지정보'!A:E,2,FALSE),"") -> https://ci.encar.com/carsdata/cars/inspection/41017047_photoPerform1.jpg | S8: =VLOOKUP(A8,inspection_detail_raw!A8:BK107,50,FALSE) -> 0 | T8: =IFERROR(VLOOKUP(TEXT(A8,"0"), inspection_detail_raw!A:BK, 51, FALSE), "알수없음") -> 0 | U8: =IFERROR(VLOOKUP(TEXT(A8,"0"), inspection_detail_raw!A:BK, 52, FALSE), "알수없음") -> 0 | V8: =IFERROR(VLOOKUP(TEXT(A8,"0"), inspection_detail_raw!A:BK, 54, FALSE), "알수없음") -> 0 | W8: =IFERROR(VLOOKUP(TEXT(A8,"0"), inspection_detail_raw!A:BK, 57, FALSE), "알수없음") -> TRUE | X8: =IFERROR(VLOOKUP(TEXT(A8,"0"), inspection_detail_raw!A:BK, 59, FALSE), "알수없음") -> [] | Y8: =VLOOKUP(A8,vehicle_detail!$A$2:$DK$101,78,FALSE) -> ["1009"] | Z8: =VLOOKUP(A8,vehicle_detail!$A$2:$DK$101,80,FALSE) -> ["001", "006", "007", "008", "014", "015", "019", "020", "024", "026", "027", "032", "033", "055", "071", "072"]
A9: 41298024 | B9: =VLOOKUP(A9,vehicle_detail!$A$2:$DK$101,111,FALSE) -> 238루8208 | C9: =VLOOKUP(A9,vehicle_detail!$A$2:$DK$101,101,FALSE) -> 흰색 | D9: =VLOOKUP(A9,list_100!$B$2:$P$101,9,FALSE) -> 현대 | E9: =VLOOKUP(A9,list_100!$B$2:$P$101,11,FALSE) -> 더 뉴 싼타페 | F9: =VLOOKUP(A9,list_100!$B$2:$P$101,2,FALSE) -> 디젤 2.2 2WD | G9: =VLOOKUP(A9,list_100!$B$2:$P$101,3,FALSE) -> 프리미엄 초이스 | H9: =VLOOKUP(A9,list_100!$B$2:$P$101,6,FALSE) -> 2021 | I9: =VLOOKUP(A9,list_100!$B$2:$P$101,7,FALSE) -> 디젤 | J9: =VLOOKUP(A9,vehicle_detail!$A$2:$DK$101,100,FALSE) -> SUV | K9: =VLOOKUP(A9,list_100!$B$2:$P$101,15,FALSE) -> 2180 | L9: =VLOOKUP(A9,list_100!$B$2:$P$101,10,FALSE) -> 117174 | M9: =VLOOKUP(A9,list_100!$B$2:$V$101,21,FALSE) -> 202012 | N9: =VLOOKUP(A9,seller_user!$A$2:$Y$101,2,FALSE) -> dksdudtn9326 | O9: =VLOOKUP(A9,seller_user!$A$2:$Y$101,25,FALSE) -> 안영수 | P9: =VLOOKUP(A9,seller_user!$A$2:$Y$101,3,FALSE) -> [{"companyType": "FIRM", "companyName": "고바우", "brn": "410-86-47910", "associationCd": 7, "associationName": "광주 자동차매매사업조합", "associationPhoneNumber": "062-384-3820", "certificatedEmployeeNumber": "18-062-00501", "address": {"zipcode": "62071 ", "location": null, "sido": "광주", "sigungu": "서구", "eupmyeondong": null, "eupmyeondongEtc": null, "address": "광주 서구 매월1로 48", "buildingCd": "2914013200106210018000001"}, "contacts": null, "used": true}] | Q9: =VLOOKUP(A9,inspection_detail_raw!A9:BK108,4,FALSE) -> ["IMAGE"] | R9: =IFERROR("https://ci.encar.com"&VLOOKUP(A9,'성능점검 이미지정보'!A:E,2,FALSE),"") -> https://ci.encar.com/carsdata/cars/inspection/41298024_I1.jpg | S9: =VLOOKUP(A9,inspection_detail_raw!A9:BK108,50,FALSE) -> 0 | T9: =IFERROR(VLOOKUP(TEXT(A9,"0"), inspection_detail_raw!A:BK, 51, FALSE), "알수없음") -> 0 | U9: =IFERROR(VLOOKUP(TEXT(A9,"0"), inspection_detail_raw!A:BK, 52, FALSE), "알수없음") -> 0 | V9: =IFERROR(VLOOKUP(TEXT(A9,"0"), inspection_detail_raw!A:BK, 54, FALSE), "알수없음") -> 0 | W9: =IFERROR(VLOOKUP(TEXT(A9,"0"), inspection_detail_raw!A:BK, 57, FALSE), "알수없음") -> FALSE | X9: =IFERROR(VLOOKUP(TEXT(A9,"0"), inspection_detail_raw!A:BK, 59, FALSE), "알수없음") -> [] | Y9: =VLOOKUP(A9,vehicle_detail!$A$2:$DK$101,78,FALSE) -> ["1035", "10002"] | Z9: =VLOOKUP(A9,vehicle_detail!$A$2:$DK$101,80,FALSE) -> ["001", "004", "005", "006", "007", "008", "014", "015", "017", "019", "020", "021", "022", "023", "024", "026", "027", "031", "032", "033", "034", "035", "055", "056", "057", "058", "059", "063", "068", "072", "074", "075", "077", "082", "084", "085", "088", "094", "096", "097"]
A10: 39870119 | B10: =VLOOKUP(A10,vehicle_detail!$A$2:$DK$101,111,FALSE) -> 25수3077 | C10: =VLOOKUP(A10,vehicle_detail!$A$2:$DK$101,101,FALSE) -> 검정색 | D10: =VLOOKUP(A10,list_100!$B$2:$P$101,9,FALSE) -> 현대 | E10: =VLOOKUP(A10,list_100!$B$2:$P$101,11,FALSE) -> 그랜저 HG | F10: =VLOOKUP(A10,list_100!$B$2:$P$101,2,FALSE) -> HG300 프라임 | G10: =VLOOKUP(A10,list_100!$B$2:$P$101,3,FALSE) -> 0 | H10: =VLOOKUP(A10,list_100!$B$2:$P$101,6,FALSE) -> 2012 | I10: =VLOOKUP(A10,list_100!$B$2:$P$101,7,FALSE) -> 가솔린 | J10: =VLOOKUP(A10,vehicle_detail!$A$2:$DK$101,100,FALSE) -> 대형차 | K10: =VLOOKUP(A10,list_100!$B$2:$P$101,15,FALSE) -> 550 | L10: =VLOOKUP(A10,list_100!$B$2:$P$101,10,FALSE) -> 123680 | M10: =VLOOKUP(A10,list_100!$B$2:$V$101,21,FALSE) -> 201206 | N10: =VLOOKUP(A10,seller_user!$A$2:$Y$101,2,FALSE) -> dksdudtn9326 | O10: =VLOOKUP(A10,seller_user!$A$2:$Y$101,25,FALSE) -> 안영수 | P10: =VLOOKUP(A10,seller_user!$A$2:$Y$101,3,FALSE) -> [{"companyType": "FIRM", "companyName": "고바우", "brn": "410-86-47910", "associationCd": 7, "associationName": "광주 자동차매매사업조합", "associationPhoneNumber": "062-384-3820", "certificatedEmployeeNumber": "18-062-00501", "address": {"zipcode": "62071 ", "location": null, "sido": "광주", "sigungu": "서구", "eupmyeondong": null, "eupmyeondongEtc": null, "address": "광주 서구 매월1로 48", "buildingCd": "2914013200106210018000001"}, "contacts": null, "used": true}] | Q10: =VLOOKUP(A10,inspection_detail_raw!A10:BK109,4,FALSE) -> ["IMAGE"] | R10: =IFERROR("https://ci.encar.com"&VLOOKUP(A10,'성능점검 이미지정보'!A:E,2,FALSE),"") -> https://ci.encar.com/carsdata/cars/inspection/39870119_I1.jpg | S10: =VLOOKUP(A10,inspection_detail_raw!A10:BK109,50,FALSE) -> 0 | T10: =IFERROR(VLOOKUP(TEXT(A10,"0"), inspection_detail_raw!A:BK, 51, FALSE), "알수없음") -> 0 | U10: =IFERROR(VLOOKUP(TEXT(A10,"0"), inspection_detail_raw!A:BK, 52, FALSE), "알수없음") -> 0 | V10: =IFERROR(VLOOKUP(TEXT(A10,"0"), inspection_detail_raw!A:BK, 54, FALSE), "알수없음") -> 0 | W10: =IFERROR(VLOOKUP(TEXT(A10,"0"), inspection_detail_raw!A:BK, 57, FALSE), "알수없음") -> FALSE | X10: =IFERROR(VLOOKUP(TEXT(A10,"0"), inspection_detail_raw!A:BK, 59, FALSE), "알수없음") -> [] | Y10: =VLOOKUP(A10,vehicle_detail!$A$2:$DK$101,78,FALSE) -> ["1031"] | Z10: =VLOOKUP(A10,vehicle_detail!$A$2:$DK$101,80,FALSE) -> ["001", "003", "004", "005", "006", "007", "008", "014", "015", "017", "019", "020", "021", "022", "023", "024", "026", "027", "030", "031", "032", "033", "034", "035", "055", "056", "057", "058", "063", "068", "071", "072", "074", "077", "082", "085", "096", "097"]
A11: 41326098 | B11: =VLOOKUP(A11,vehicle_detail!$A$2:$DK$101,111,FALSE) -> 358저1935 | C11: =VLOOKUP(A11,vehicle_detail!$A$2:$DK$101,101,FALSE) -> 흰색 | D11: =VLOOKUP(A11,list_100!$B$2:$P$101,9,FALSE) -> 현대 | E11: =VLOOKUP(A11,list_100!$B$2:$P$101,11,FALSE) -> 아반떼 (CN7) | F11: =VLOOKUP(A11,list_100!$B$2:$P$101,2,FALSE) -> 1.6 LPi (렌터카) | G11: =VLOOKUP(A11,list_100!$B$2:$P$101,3,FALSE) -> 스마트 | H11: =VLOOKUP(A11,list_100!$B$2:$P$101,6,FALSE) -> 2023 | I11: =VLOOKUP(A11,list_100!$B$2:$P$101,7,FALSE) -> LPG(일반인 구입) | J11: =VLOOKUP(A11,vehicle_detail!$A$2:$DK$101,100,FALSE) -> 준중형차 | K11: =VLOOKUP(A11,list_100!$B$2:$P$101,15,FALSE) -> 1099 | L11: =VLOOKUP(A11,list_100!$B$2:$P$101,10,FALSE) -> 90742 | M11: =VLOOKUP(A11,list_100!$B$2:$V$101,21,FALSE) -> 202205 | N11: =VLOOKUP(A11,seller_user!$A$2:$Y$101,2,FALSE) -> dnfltnghk92 | O11: =VLOOKUP(A11,seller_user!$A$2:$Y$101,25,FALSE) -> 신윤석 | P11: =VLOOKUP(A11,seller_user!$A$2:$Y$101,3,FALSE) -> [{"companyType": "FIRM", "companyName": "카메이트", "brn": "438-18-00082", "associationCd": 28, "associationName": "경기 자동차매매사업조합", "associationPhoneNumber": "031-242-8940", "certificatedEmployeeNumber": "GC21-05732", "address": {"zipcode": "16602 ", "location": null, "sido": "경기", "sigungu": "수원시 권선구", "eupmyeondong": null, "eupmyeondongEtc": null, "address": "경기 수원시 권선구 권선로 308", "buildingCd": "4111312800100140134000001"}, "contacts": null, "used": true}] | Q11: =VLOOKUP(A11,inspection_detail_raw!A11:BK110,4,FALSE) -> ["IMAGE"] | R11: =IFERROR("https://ci.encar.com"&VLOOKUP(A11,'성능점검 이미지정보'!A:E,2,FALSE),"") -> https://ci.encar.com/carsdata/cars/inspection/41326098_photoPerform1.jpg | S11: =VLOOKUP(A11,inspection_detail_raw!A11:BK110,50,FALSE) -> 0 | T11: =IFERROR(VLOOKUP(TEXT(A11,"0"), inspection_detail_raw!A:BK, 51, FALSE), "알수없음") -> 0 | U11: =IFERROR(VLOOKUP(TEXT(A11,"0"), inspection_detail_raw!A:BK, 52, FALSE), "알수없음") -> 0 | V11: =IFERROR(VLOOKUP(TEXT(A11,"0"), inspection_detail_raw!A:BK, 54, FALSE), "알수없음") -> 0 | W11: =IFERROR(VLOOKUP(TEXT(A11,"0"), inspection_detail_raw!A:BK, 57, FALSE), "알수없음") -> TRUE | X11: =IFERROR(VLOOKUP(TEXT(A11,"0"), inspection_detail_raw!A:BK, 59, FALSE), "알수없음") -> [] | Y11: =VLOOKUP(A11,vehicle_detail!$A$2:$DK$101,78,FALSE) -> ["1045"] | Z11: =VLOOKUP(A11,vehicle_detail!$A$2:$DK$101,80,FALSE) -> ["001", "004", "006", "007", "008", "014", "015", "017", "019", "020", "022", "024", "026", "027", "030", "031", "032", "033", "055", "056", "057", "058", "068", "072", "074", "088", "096", "097"]
A12: 41307028 | B12: =VLOOKUP(A12,vehicle_detail!$A$2:$DK$101,111,FALSE) -> 03어9563 | C12: =VLOOKUP(A12,vehicle_detail!$A$2:$DK$101,101,FALSE) -> 흰색 | D12: =VLOOKUP(A12,list_100!$B$2:$P$101,9,FALSE) -> 현대 | E12: =VLOOKUP(A12,list_100!$B$2:$P$101,11,FALSE) -> 쏘나타 뉴 라이즈 | F12: =VLOOKUP(A12,list_100!$B$2:$P$101,2,FALSE) -> LPI 프리미엄 | G12: =VLOOKUP(A12,list_100!$B$2:$P$101,3,FALSE) -> 0 | H12: =VLOOKUP(A12,list_100!$B$2:$P$101,6,FALSE) -> 2018 | I12: =VLOOKUP(A12,list_100!$B$2:$P$101,7,FALSE) -> LPG(일반인 구입) | J12: =VLOOKUP(A12,vehicle_detail!$A$2:$DK$101,100,FALSE) -> 중형차 | K12: =VLOOKUP(A12,list_100!$B$2:$P$101,15,FALSE) -> 1200 | L12: =VLOOKUP(A12,list_100!$B$2:$P$101,10,FALSE) -> 137276 | M12: =VLOOKUP(A12,list_100!$B$2:$V$101,21,FALSE) -> 201707 | N12: =VLOOKUP(A12,seller_user!$A$2:$Y$101,2,FALSE) -> dksdudtn9326 | O12: =VLOOKUP(A12,seller_user!$A$2:$Y$101,25,FALSE) -> 안영수 | P12: =VLOOKUP(A12,seller_user!$A$2:$Y$101,3,FALSE) -> [{"companyType": "FIRM", "companyName": "고바우", "brn": "410-86-47910", "associationCd": 7, "associationName": "광주 자동차매매사업조합", "associationPhoneNumber": "062-384-3820", "certificatedEmployeeNumber": "18-062-00501", "address": {"zipcode": "62071 ", "location": null, "sido": "광주", "sigungu": "서구", "eupmyeondong": null, "eupmyeondongEtc": null, "address": "광주 서구 매월1로 48", "buildingCd": "2914013200106210018000001"}, "contacts": null, "used": true}] | Q12: =VLOOKUP(A12,inspection_detail_raw!A12:BK111,4,FALSE) -> ["IMAGE"] | R12: =IFERROR("https://ci.encar.com"&VLOOKUP(A12,'성능점검 이미지정보'!A:E,2,FALSE),"") -> https://ci.encar.com/carsdata/cars/inspection/41307028_I1.jpg | S12: =VLOOKUP(A12,inspection_detail_raw!A12:BK111,50,FALSE) -> 0 | T12: =IFERROR(VLOOKUP(TEXT(A12,"0"), inspection_detail_raw!A:BK, 51, FALSE), "알수없음") -> 0 | U12: =IFERROR(VLOOKUP(TEXT(A12,"0"), inspection_detail_raw!A:BK, 52, FALSE), "알수없음") -> 0 | V12: =IFERROR(VLOOKUP(TEXT(A12,"0"), inspection_detail_raw!A:BK, 54, FALSE), "알수없음") -> 0 | W12: =IFERROR(VLOOKUP(TEXT(A12,"0"), inspection_detail_raw!A:BK, 57, FALSE), "알수없음") -> TRUE | X12: =IFERROR(VLOOKUP(TEXT(A12,"0"), inspection_detail_raw!A:BK, 59, FALSE), "알수없음") -> [] | Y12: =VLOOKUP(A12,vehicle_detail!$A$2:$DK$101,78,FALSE) -> [] | Z12: =VLOOKUP(A12,vehicle_detail!$A$2:$DK$101,80,FALSE) -> ["001", "004", "006", "007", "008", "014", "015", "017", "019", "020", "021", "022", "023", "024", "026", "027", "030", "031", "032", "033", "034", "035", "051", "055", "056", "057", "058", "063", "068", "071", "072", "074", "077", "082", "087", "094", "096", "097"]
A13: 41376170 | B13: =VLOOKUP(A13,vehicle_detail!$A$2:$DK$101,111,FALSE) -> 320머9540 | C13: =VLOOKUP(A13,vehicle_detail!$A$2:$DK$101,101,FALSE) -> 검정색 | D13: =VLOOKUP(A13,list_100!$B$2:$P$101,9,FALSE) -> 현대 | E13: =VLOOKUP(A13,list_100!$B$2:$P$101,11,FALSE) -> 쏘나타 (DN8) | F13: =VLOOKUP(A13,list_100!$B$2:$P$101,2,FALSE) -> 2.0 | G13: =VLOOKUP(A13,list_100!$B$2:$P$101,3,FALSE) -> 프리미엄 | H13: =VLOOKUP(A13,list_100!$B$2:$P$101,6,FALSE) -> 2020 | I13: =VLOOKUP(A13,list_100!$B$2:$P$101,7,FALSE) -> 가솔린 | J13: =VLOOKUP(A13,vehicle_detail!$A$2:$DK$101,100,FALSE) -> 중형차 | K13: =VLOOKUP(A13,list_100!$B$2:$P$101,15,FALSE) -> 1199 | L13: =VLOOKUP(A13,list_100!$B$2:$P$101,10,FALSE) -> 131174 | M13: =VLOOKUP(A13,list_100!$B$2:$V$101,21,FALSE) -> 201911 | N13: =VLOOKUP(A13,seller_user!$A$2:$Y$101,2,FALSE) -> dnfltnghk92 | O13: =VLOOKUP(A13,seller_user!$A$2:$Y$101,25,FALSE) -> 신윤석 | P13: =VLOOKUP(A13,seller_user!$A$2:$Y$101,3,FALSE) -> [{"companyType": "FIRM", "companyName": "카메이트", "brn": "438-18-00082", "associationCd": 28, "associationName": "경기 자동차매매사업조합", "associationPhoneNumber": "031-242-8940", "certificatedEmployeeNumber": "GC21-05732", "address": {"zipcode": "16602 ", "location": null, "sido": "경기", "sigungu": "수원시 권선구", "eupmyeondong": null, "eupmyeondongEtc": null, "address": "경기 수원시 권선구 권선로 308", "buildingCd": "4111312800100140134000001"}, "contacts": null, "used": true}] | Q13: =VLOOKUP(A13,inspection_detail_raw!A13:BK112,4,FALSE) -> ["IMAGE"] | R13: =IFERROR("https://ci.encar.com"&VLOOKUP(A13,'성능점검 이미지정보'!A:E,2,FALSE),"") -> https://ci.encar.com/carsdata/cars/inspection/41376170_photoPerform1.jpg | S13: =VLOOKUP(A13,inspection_detail_raw!A13:BK112,50,FALSE) -> 0 | T13: =IFERROR(VLOOKUP(TEXT(A13,"0"), inspection_detail_raw!A:BK, 51, FALSE), "알수없음") -> 0 | U13: =IFERROR(VLOOKUP(TEXT(A13,"0"), inspection_detail_raw!A:BK, 52, FALSE), "알수없음") -> 0 | V13: =IFERROR(VLOOKUP(TEXT(A13,"0"), inspection_detail_raw!A:BK, 54, FALSE), "알수없음") -> 0 | W13: =IFERROR(VLOOKUP(TEXT(A13,"0"), inspection_detail_raw!A:BK, 57, FALSE), "알수없음") -> TRUE | X13: =IFERROR(VLOOKUP(TEXT(A13,"0"), inspection_detail_raw!A:BK, 59, FALSE), "알수없음") -> [] | Y13: =VLOOKUP(A13,vehicle_detail!$A$2:$DK$101,78,FALSE) -> ["10004"] | Z13: =VLOOKUP(A13,vehicle_detail!$A$2:$DK$101,80,FALSE) -> ["001", "004", "005", "006", "007", "008", "014", "015", "017", "019", "020", "021", "022", "023", "024", "026", "027", "030", "031", "032", "033", "055", "056", "057", "058", "068", "072", "074", "075", "082", "084", "088", "094", "096", "097"]
A14: 41381376 | B14: =VLOOKUP(A14,vehicle_detail!$A$2:$DK$101,111,FALSE) -> 129부2816 | C14: =VLOOKUP(A14,vehicle_detail!$A$2:$DK$101,101,FALSE) -> 흰색 | D14: =VLOOKUP(A14,list_100!$B$2:$P$101,9,FALSE) -> 현대 | E14: =VLOOKUP(A14,list_100!$B$2:$P$101,11,FALSE) -> 쏘나타 뉴 라이즈 | F14: =VLOOKUP(A14,list_100!$B$2:$P$101,2,FALSE) -> 2.0 스타일 | G14: =VLOOKUP(A14,list_100!$B$2:$P$101,3,FALSE) -> 0 | H14: =VLOOKUP(A14,list_100!$B$2:$P$101,6,FALSE) -> 2019 | I14: =VLOOKUP(A14,list_100!$B$2:$P$101,7,FALSE) -> 가솔린 | J14: =VLOOKUP(A14,vehicle_detail!$A$2:$DK$101,100,FALSE) -> 중형차 | K14: =VLOOKUP(A14,list_100!$B$2:$P$101,15,FALSE) -> 709 | L14: =VLOOKUP(A14,list_100!$B$2:$P$101,10,FALSE) -> 120207 | M14: =VLOOKUP(A14,list_100!$B$2:$V$101,21,FALSE) -> 201810 | N14: =VLOOKUP(A14,seller_user!$A$2:$Y$101,2,FALSE) -> dnfltnghk92 | O14: =VLOOKUP(A14,seller_user!$A$2:$Y$101,25,FALSE) -> 신윤석 | P14: =VLOOKUP(A14,seller_user!$A$2:$Y$101,3,FALSE) -> [{"companyType": "FIRM", "companyName": "카메이트", "brn": "438-18-00082", "associationCd": 28, "associationName": "경기 자동차매매사업조합", "associationPhoneNumber": "031-242-8940", "certificatedEmployeeNumber": "GC21-05732", "address": {"zipcode": "16602 ", "location": null, "sido": "경기", "sigungu": "수원시 권선구", "eupmyeondong": null, "eupmyeondongEtc": null, "address": "경기 수원시 권선구 권선로 308", "buildingCd": "4111312800100140134000001"}, "contacts": null, "used": true}] | Q14: =VLOOKUP(A14,inspection_detail_raw!A14:BK113,4,FALSE) -> ["IMAGE"] | R14: =IFERROR("https://ci.encar.com"&VLOOKUP(A14,'성능점검 이미지정보'!A:E,2,FALSE),"") -> https://ci.encar.com/carsdata/cars/inspection/41381376_photoPerform1.jpg | S14: =VLOOKUP(A14,inspection_detail_raw!A14:BK113,50,FALSE) -> 0 | T14: =IFERROR(VLOOKUP(TEXT(A14,"0"), inspection_detail_raw!A:BK, 51, FALSE), "알수없음") -> 0 | U14: =IFERROR(VLOOKUP(TEXT(A14,"0"), inspection_detail_raw!A:BK, 52, FALSE), "알수없음") -> 0 | V14: =IFERROR(VLOOKUP(TEXT(A14,"0"), inspection_detail_raw!A:BK, 54, FALSE), "알수없음") -> 0 | W14: =IFERROR(VLOOKUP(TEXT(A14,"0"), inspection_detail_raw!A:BK, 57, FALSE), "알수없음") -> TRUE | X14: =IFERROR(VLOOKUP(TEXT(A14,"0"), inspection_detail_raw!A:BK, 59, FALSE), "알수없음") -> [] | Y14: =VLOOKUP(A14,vehicle_detail!$A$2:$DK$101,78,FALSE) -> [] | Z14: =VLOOKUP(A14,vehicle_detail!$A$2:$DK$101,80,FALSE) -> ["001", "006", "007", "008", "014", "015", "017", "019", "020", "022", "024", "026", "027", "031", "032", "033", "055", "056", "058", "071", "072", "096"]
... A29: 41398674 | B29: =VLOOKUP(A29,vehicle_detail!$A$2:$DK$101,111,FALSE) -> 11서0515 | C29: =VLOOKUP(A29,vehicle_detail!$A$2:$DK$101,101,FALSE) -> 은색 | D29: =VLOOKUP(A29,list_100!$B$2:$P$101,9,FALSE) -> 현대 | E29: =VLOOKUP(A29,list_100!$B$2:$P$101,11,FALSE) -> 싼타페 DM | F29: =VLOOKUP(A29,list_100!$B$2:$P$101,2,FALSE) -> 디젤(e-VGT) 2.0 2WD 모던 | G29: =VLOOKUP(A29,list_100!$B$2:$P$101,3,FALSE) -> 0 | H29: =VLOOKUP(A29,list_100!$B$2:$P$101,6,FALSE) -> 2015 | I29: =VLOOKUP(A29,list_100!$B$2:$P$101,7,FALSE) -> 디젤 | J29: =VLOOKUP(A29,vehicle_detail!$A$2:$DK$101,100,FALSE) -> SUV | K29: =VLOOKUP(A29,list_100!$B$2:$P$101,15,FALSE) -> 870 | L29: =VLOOKUP(A29,list_100!$B$2:$P$101,10,FALSE) -> 140796 | M29: =VLOOKUP(A29,list_100!$B$2:$V$101,21,FALSE) -> 201504 | N29: =VLOOKUP(A29,seller_user!$A$2:$Y$101,2,FALSE) -> gold99 | O29: =VLOOKUP(A29,seller_user!$A$2:$Y$101,25,FALSE) -> 방성희 | P29: =VLOOKUP(A29,seller_user!$A$2:$Y$101,3,FALSE) -> [{"companyType": "FIRM", "companyName": "조이 모터스", "brn": "122-38-50384", "associationCd": 11, "associationName": "충남 자동차매매사업조합", "associationPhoneNumber": "041-572-8444", "certificatedEmployeeNumber": "23-041-00110", "address": {"zipcode": "31074 ", "location": null, "sido": "충남", "sigungu": "천안시 서북구", "eupmyeondong": null, "eupmyeondongEtc": null, "address": "충남 천안시 서북구", "buildingCd": "4413310500103350001040409"}, "contacts": null, "used": true}] | Q29: =VLOOKUP(A29,inspection_detail_raw!A29:BK128,4,FALSE) -> ["TABLE"] | R29: =IFERROR("https://ci.encar.com"&VLOOKUP(A29,'성능점검 이미지정보'!A:E,2,FALSE),"") | S29: =VLOOKUP(A29,inspection_detail_raw!A29:BK128,50,FALSE) -> [{"code": "1", "title": "렌트"}] | T29: =IFERROR(VLOOKUP(TEXT(A29,"0"), inspection_detail_raw!A:BK, 51, FALSE), "알수없음") -> 20260402 | U29: =IFERROR(VLOOKUP(TEXT(A29,"0"), inspection_detail_raw!A:BK, 52, FALSE), "알수없음") -> 20240403 | V29: =IFERROR(VLOOKUP(TEXT(A29,"0"), inspection_detail_raw!A:BK, 54, FALSE), "알수없음") -> KMHSU81UBFU492918 | W29: =IFERROR(VLOOKUP(TEXT(A29,"0"), inspection_detail_raw!A:BK, 57, FALSE), "알수없음") -> TRUE | X29: =IFERROR(VLOOKUP(TEXT(A29,"0"), inspection_detail_raw!A:BK, 59, FALSE), "알수없음") -> [{"type": {"code": "P062", "title": "쿼터 패널(우)"}, "statusTypes": [{"code": "X", "title": "교환(교체)"}], "attributes": ["RANK_TWO"]}] | Y29: =VLOOKUP(A29,vehicle_detail!$A$2:$DK$101,78,FALSE) -> ["1042", "1040", "1043"] | Z29: =VLOOKUP(A29,vehicle_detail!$A$2:$DK$101,80,FALSE) -> ["001", "003", "004", "005", "006", "007", "008", "014", "015", "017", "019", "020", "021", "022", "023", "024", "026", "027", "030", "031", "032", "033", "055", "056", "057", "058", "063", "068", "071", "072", "074", "082", "096", "097"]
A30: 41130226 | B30: =VLOOKUP(A30,vehicle_detail!$A$2:$DK$101,111,FALSE) -> 243구5409 | C30: =VLOOKUP(A30,vehicle_detail!$A$2:$DK$101,101,FALSE) -> 쥐색 | D30: =VLOOKUP(A30,list_100!$B$2:$P$101,9,FALSE) -> 현대 | E30: =VLOOKUP(A30,list_100!$B$2:$P$101,11,FALSE) -> 싼타페 TM | F30: =VLOOKUP(A30,list_100!$B$2:$P$101,2,FALSE) -> 가솔린 2.0T 2WD | G30: =VLOOKUP(A30,list_100!$B$2:$P$101,3,FALSE) -> 익스클루시브 | H30: =VLOOKUP(A30,list_100!$B$2:$P$101,6,FALSE) -> 2020 | I30: =VLOOKUP(A30,list_100!$B$2:$P$101,7,FALSE) -> 가솔린 | J30: =VLOOKUP(A30,vehicle_detail!$A$2:$DK$101,100,FALSE) -> SUV | K30: =VLOOKUP(A30,list_100!$B$2:$P$101,15,FALSE) -> 2060 | L30: =VLOOKUP(A30,list_100!$B$2:$P$101,10,FALSE) -> 96517 | M30: =VLOOKUP(A30,list_100!$B$2:$V$101,21,FALSE) -> 202006 | N30: =VLOOKUP(A30,seller_user!$A$2:$Y$101,2,FALSE) -> kcardgbyw | O30: =VLOOKUP(A30,seller_user!$A$2:$Y$101,25,FALSE) -> 김병훈 | P30: =VLOOKUP(A30,seller_user!$A$2:$Y$101,3,FALSE) -> [{"companyType": "FIRM", "companyName": "오토플러스(주)", "brn": "105-86-06429", "associationCd": 3, "associationName": "대구 자동차매매사업조합", "associationPhoneNumber": "053-341-7788", "certificatedEmployeeNumber": "2305300328", "address": {"zipcode": "41081 ", "location": null, "sido": "대구", "sigungu": "동구", "eupmyeondong": null, "eupmyeondongEtc": null, "address": "대구 동구", "buildingCd": "2714012300103010001033011"}, "contacts": null, "used": true}] | Q30: =VLOOKUP(A30,inspection_detail_raw!A30:BK129,4,FALSE) -> ["TABLE"] | R30: =IFERROR("https://ci.encar.com"&VLOOKUP(A30,'성능점검 이미지정보'!A:E,2,FALSE),"") | S30: =IFERROR(VLOOKUP(TEXT(A30,"0"), inspection_detail_raw!A:BK, 50, FALSE), "알수없음") -> [] | T30: =IFERROR(VLOOKUP(TEXT(A30,"0"), inspection_detail_raw!A:BK, 51, FALSE), "알수없음") -> 20260608 | U30: =IFERROR(VLOOKUP(TEXT(A30,"0"), inspection_detail_raw!A:BK, 52, FALSE), "알수없음") -> 20240609 | V30: =IFERROR(VLOOKUP(TEXT(A30,"0"), inspection_detail_raw!A:BK, 54, FALSE), "알수없음") -> KMHS281ABLU298577 | W30: =IFERROR(VLOOKUP(TEXT(A30,"0"), inspection_detail_raw!A:BK, 57, FALSE), "알수없음") -> FALSE | X30: =IFERROR(VLOOKUP(TEXT(A30,"0"), inspection_detail_raw!A:BK, 59, FALSE), "알수없음") -> [] | Y30: =VLOOKUP(A30,vehicle_detail!$A$2:$DK$101,78,FALSE) -> ["10001"] | Z30: =VLOOKUP(A30,vehicle_detail!$A$2:$DK$101,80,FALSE) -> ["001", "004", "005", "006", "007", "008", "014", "015", "017", "019", "020", "021", "022", "023", "024", "026", "027", "030", "031", "032", "033", "034", "055", "056", "057", "058", "059", "062", "063", "072", "074", "077", "079", "082", "085", "088", "094", "096", "097"]
A31: 40988766 | B31: =VLOOKUP(A31,vehicle_detail!$A$2:$DK$101,111,FALSE) -> 27가3348 | C31: =VLOOKUP(A31,vehicle_detail!$A$2:$DK$101,101,FALSE) -> 검정색 | D31: =VLOOKUP(A31,list_100!$B$2:$P$101,9,FALSE) -> 현대 | E31: =VLOOKUP(A31,list_100!$B$2:$P$101,11,FALSE) -> 그랜저 HG 하이브리드 | F31: =VLOOKUP(A31,list_100!$B$2:$P$101,2,FALSE) -> 프리미엄 | G31: =VLOOKUP(A31,list_100!$B$2:$P$101,3,FALSE) -> 0 | H31: =VLOOKUP(A31,list_100!$B$2:$P$101,6,FALSE) -> 2015 | I31: =VLOOKUP(A31,list_100!$B$2:$P$101,7,FALSE) -> 가솔린+전기 | J31: =VLOOKUP(A31,vehicle_detail!$A$2:$DK$101,100,FALSE) -> 대형차 | K31: =VLOOKUP(A31,list_100!$B$2:$P$101,15,FALSE) -> 649 | L31: =VLOOKUP(A31,list_100!$B$2:$P$101,10,FALSE) -> 191302 | M31: =VLOOKUP(A31,list_100!$B$2:$V$101,21,FALSE) -> 201409 | N31: =VLOOKUP(A31,seller_user!$A$2:$Y$101,2,FALSE) -> nobility4569 | O31: =VLOOKUP(A31,seller_user!$A$2:$Y$101,25,FALSE) -> 박효진 | P31: =VLOOKUP(A31,seller_user!$A$2:$Y$101,3,FALSE) -> [{"companyType": "FIRM", "companyName": "그차는내차", "brn": "130-48-00545", "associationCd": 23, "associationName": "대구연합 자동차매매사업조합", "associationPhoneNumber": "053-584-9900", "certificatedEmployeeNumber": "DG19-00889", "address": {"zipcode": "41752 ", "location": null, "sido": "대구", "sigungu": "서구", "eupmyeondong": null, "eupmyeondongEtc": null, "address": "대구 서구 문화로 37", "buildingCd": "2717010600100420030000001"}, "contacts": null, "used": true}] | Q31: =VLOOKUP(A31,inspection_detail_raw!A31:BK130,4,FALSE) -> ["TABLE"] | R31: =IFERROR("https://ci.encar.com"&VLOOKUP(A31,'성능점검 이미지정보'!A:E,2,FALSE),"") | S31: =VLOOKUP(A31,inspection_detail_raw!A31:BK130,50,FALSE) -> [] | T31: =IFERROR(VLOOKUP(TEXT(A31,"0"), inspection_detail_raw!A:BK, 51, FALSE), "알수없음") -> 20260918 | U31: =IFERROR(VLOOKUP(TEXT(A31,"0"), inspection_detail_raw!A:BK, 52, FALSE), "알수없음") -> 20240919 | V31: =IFERROR(VLOOKUP(TEXT(A31,"0"), inspection_detail_raw!A:BK, 54, FALSE), "알수없음") -> KMHFG413BFA009859 | W31: =IFERROR(VLOOKUP(TEXT(A31,"0"), inspection_detail_raw!A:BK, 57, FALSE), "알수없음") -> TRUE | X31: =IFERROR(VLOOKUP(TEXT(A31,"0"), inspection_detail_raw!A:BK, 59, FALSE), "알수없음") -> [{"type": {"code": "P062", "title": "쿼터 패널(우)"}, "statusTypes": [{"code": "W", "title": "판금/용접"}], "attributes": ["RANK_TWO"]}] | Y31: =VLOOKUP(A31,vehicle_detail!$A$2:$DK$101,78,FALSE) -> ["1004", "1008"] | Z31: =VLOOKUP(A31,vehicle_detail!$A$2:$DK$101,80,FALSE) -> ["001", "003", "004", "005", "006", "007", "008", "014", "015", "017", "019", "020", "021", "022", "023", "024", "026", "027", "030", "031", "032", "033", "034", "035", "051", "055", "056", "057", "058", "063", "068", "071", "072", "074", "077", "082", "085", "094", "096", "097"]
A32: 41388391 | B32: =VLOOKUP(A32,vehicle_detail!$A$2:$DK$101,111,FALSE) -> 105마5870 | C32: =VLOOKUP(A32,vehicle_detail!$A$2:$DK$101,101,FALSE) -> 쥐색 | D32: =VLOOKUP(A32,list_100!$B$2:$P$101,9,FALSE) -> 현대 | E32: =VLOOKUP(A32,list_100!$B$2:$P$101,11,FALSE) -> 그랜저 IG | F32: =VLOOKUP(A32,list_100!$B$2:$P$101,2,FALSE) -> 3.0 LPi 익스클루시브 (렌터카) | G32: =VLOOKUP(A32,list_100!$B$2:$P$101,3,FALSE) -> 0 | H32: =VLOOKUP(A32,list_100!$B$2:$P$101,6,FALSE) -> 2017 | I32: =VLOOKUP(A32,list_100!$B$2:$P$101,7,FALSE) -> LPG(일반인 구입) | J32: =VLOOKUP(A32,vehicle_detail!$A$2:$DK$101,100,FALSE) -> 대형차 | K32: =VLOOKUP(A32,list_100!$B$2:$P$101,15,FALSE) -> 1259 | L32: =VLOOKUP(A32,list_100!$B$2:$P$101,10,FALSE) -> 184927 | M32: =VLOOKUP(A32,list_100!$B$2:$V$101,21,FALSE) -> 201702 | N32: =VLOOKUP(A32,seller_user!$A$2:$Y$101,2,FALSE) -> tankdotcom | O32: =VLOOKUP(A32,seller_user!$A$2:$Y$101,25,FALSE) -> 강현진 | P32: =VLOOKUP(A32,seller_user!$A$2:$Y$101,3,FALSE) -> [{"companyType": "FIRM", "companyName": "미소모터스", "brn": "531-25-01637", "associationCd": 0, "associationName": "서울 자동차매매사업조합", "associationPhoneNumber": "02-847-3448", "certificatedEmployeeNumber": "SE23-00659", "address": {"zipcode": "07909 ", "location": null, "sido": "서울", "sigungu": "양천구", "eupmyeondong": null, "eupmyeondongEtc": null, "address": "서울 양천구", "buildingCd": "1147010300100390001012768"}, "contacts": null, "used": true}] | Q32: =VLOOKUP(A32,inspection_detail_raw!A32:BK131,4,FALSE) -> ["TABLE"] | R32: =IFERROR("https://ci.encar.com"&VLOOKUP(A32,'성능점검 이미지정보'!A:E,2,FALSE),"") | S32: =VLOOKUP(A32,inspection_detail_raw!A32:BK131,50,FALSE) -> [{"code": "1", "title": "렌트"}] | T32: =IFERROR(VLOOKUP(TEXT(A32,"0"), inspection_detail_raw!A:BK, 51, FALSE), "알수없음") -> 20270331 | U32: =IFERROR(VLOOKUP(TEXT(A32,"0"), inspection_detail_raw!A:BK, 52, FALSE), "알수없음") -> 20250401 | V32: =IFERROR(VLOOKUP(TEXT(A32,"0"), inspection_detail_raw!A:BK, 54, FALSE), "알수없음") -> KMHF641NBHA030476 | W32: =IFERROR(VLOOKUP(TEXT(A32,"0"), inspection_detail_raw!A:BK, 57, FALSE), "알수없음") -> FALSE | X32: =IFERROR(VLOOKUP(TEXT(A32,"0"), inspection_detail_raw!A:BK, 59, FALSE), "알수없음") -> [] | Y32: =VLOOKUP(A32,vehicle_detail!$A$2:$DK$101,78,FALSE) -> [] | Z32: =VLOOKUP(A32,vehicle_detail!$A$2:$DK$101,80,FALSE) -> ["001", "004", "005", "006", "007", "008", "010", "014", "015", "017", "019", "020", "021", "022", "023", "024", "026", "027", "030", "031", "032", "033", "034", "035", "051", "055", "056", "057", "058", "063", "068", "071", "072", "074", "075", "077", "081", "082", "083", "085", "087", "092", "093", "094", "095", "096", "097"]
A33: 41369527 | B33: =VLOOKUP(A33,vehicle_detail!$A$2:$DK$101,111,FALSE) -> 333버6671 | C33: =VLOOKUP(A33,vehicle_detail!$A$2:$DK$101,101,FALSE) -> 연두색 | D33: =VLOOKUP(A33,list_100!$B$2:$P$101,9,FALSE) -> 현대 | E33: =VLOOKUP(A33,list_100!$B$2:$P$101,11,FALSE) -> 캐스퍼 | F33: =VLOOKUP(A33,list_100!$B$2:$P$101,2,FALSE) -> 밴 | G33: =VLOOKUP(A33,list_100!$B$2:$P$101,3,FALSE) -> 스마트 | H33: =VLOOKUP(A33,list_100!$B$2:$P$101,6,FALSE) -> 2023 | I33: =VLOOKUP(A33,list_100!$B$2:$P$101,7,FALSE) -> 가솔린 | J33: =VLOOKUP(A33,vehicle_detail!$A$2:$DK$101,100,FALSE) -> 경차 | K33: =VLOOKUP(A33,list_100!$B$2:$P$101,15,FALSE) -> 1390 | L33: =VLOOKUP(A33,list_100!$B$2:$P$101,10,FALSE) -> 9473 | M33: =VLOOKUP(A33,list_100!$B$2:$V$101,21,FALSE) -> 202203 | N33: =VLOOKUP(A33,seller_user!$A$2:$Y$101,2,FALSE) -> ef9550 | O33: =VLOOKUP(A33,seller_user!$A$2:$Y$101,25,FALSE) -> 김동호 | P33: =VLOOKUP(A33,seller_user!$A$2:$Y$101,3,FALSE) -> [{"companyType": "FIRM", "companyName": "디에이치모터스", "brn": "479-60-00627", "associationCd": 27, "associationName": "인천엠파크 자동차매매사업조합", "associationPhoneNumber": "032-715-5533", "certificatedEmployeeNumber": "IM23-00493", "address": {"zipcode": "22836 ", "location": null, "sido": "인천", "sigungu": "서구", "eupmyeondong": null, "eupmyeondongEtc": null, "address": "인천 서구", "buildingCd": "2826011200101500019000001"}, "contacts": null, "used": true}] | Q33: =VLOOKUP(A33,inspection_detail_raw!A33:BK132,4,FALSE) -> ["TABLE"] | R33: =IFERROR("https://ci.encar.com"&VLOOKUP(A33,'성능점검 이미지정보'!A:E,2,FALSE),"") -> https://ci.encar.com/carsdata/cars/inspection/41369527_photoFront.jpg | S33: =VLOOKUP(A33,inspection_detail_raw!A33:BK132,50,FALSE) -> [{"code": "1", "title": "렌트"}] | T33: =IFERROR(VLOOKUP(TEXT(A33,"0"), inspection_detail_raw!A:BK, 51, FALSE), "알수없음") -> 20270322 | U33: =IFERROR(VLOOKUP(TEXT(A33,"0"), inspection_detail_raw!A:BK, 52, FALSE), "알수없음") -> 20260323 | V33: =IFERROR(VLOOKUP(TEXT(A33,"0"), inspection_detail_raw!A:BK, 54, FALSE), "알수없음") -> KMHB3918BPW020416 | W33: =IFERROR(VLOOKUP(TEXT(A33,"0"), inspection_detail_raw!A:BK, 57, FALSE), "알수없음") -> FALSE | X33: =IFERROR(VLOOKUP(TEXT(A33,"0"), inspection_detail_raw!A:BK, 59, FALSE), "알수없음") -> [] | Y33: =VLOOKUP(A33,vehicle_detail!$A$2:$DK$101,78,FALSE) -> ["1003", "1004"] | Z33: =VLOOKUP(A33,vehicle_detail!$A$2:$DK$101,80,FALSE) -> ["001", "006", "007", "008", "014", "015", "019", "020", "022", "024", "026", "027", "031", "032", "033", "034", "055", "056", "068", "072", "074", "082", "088", "096", "097"]
A34: 41390598 | B34: =VLOOKUP(A34,vehicle_detail!$A$2:$DK$101,111,FALSE) -> 204러4689 | C34: =VLOOKUP(A34,vehicle_detail!$A$2:$DK$101,101,FALSE) -> 검정색 | D34: =VLOOKUP(A34,list_100!$B$2:$P$101,9,FALSE) -> 현대 | E34: =VLOOKUP(A34,list_100!$B$2:$P$101,11,FALSE) -> 팰리세이드 | F34: =VLOOKUP(A34,list_100!$B$2:$P$101,2,FALSE) -> 디젤 2.2 4WD | G34: =VLOOKUP(A34,list_100!$B$2:$P$101,3,FALSE) -> 프레스티지 | H34: =VLOOKUP(A34,list_100!$B$2:$P$101,6,FALSE) -> 2021 | I34: =VLOOKUP(A34,list_100!$B$2:$P$101,7,FALSE) -> 디젤 | J34: =VLOOKUP(A34,vehicle_detail!$A$2:$DK$101,100,FALSE) -> SUV | K34: =VLOOKUP(A34,list_100!$B$2:$P$101,15,FALSE) -> 2950 | L34: =VLOOKUP(A34,list_100!$B$2:$P$101,10,FALSE) -> 86631 | M34: =VLOOKUP(A34,list_100!$B$2:$V$101,21,FALSE) -> 202011 | N34: =VLOOKUP(A34,seller_user!$A$2:$Y$101,2,FALSE) -> aka3319 | O34: =VLOOKUP(A34,seller_user!$A$2:$Y$101,25,FALSE) -> 전영수 | P34: =VLOOKUP(A34,seller_user!$A$2:$Y$101,3,FALSE) -> [{"companyType": "FIRM", "companyName": "세븐", "brn": "555-22-01592", "associationCd": 6, "associationName": "부산 자동차매매사업조합", "associationPhoneNumber": "051-868-8388", "certificatedEmployeeNumber": "23-051-36503", "address": {"zipcode": "49472 ", "location": null, "sido": "부산", "sigungu": "사하구", "eupmyeondong": null, "eupmyeondongEtc": null, "address": "부산 사하구", "buildingCd": "2638010400103700046037836"}, "contacts": null, "used": true}] | Q34: =VLOOKUP(A34,inspection_detail_raw!A34:BK133,4,FALSE) -> ["TABLE"] | R34: =IFERROR("https://ci.encar.com"&VLOOKUP(A34,'성능점검 이미지정보'!A:E,2,FALSE),"") | S34: =VLOOKUP(A34,inspection_detail_raw!A34:BK133,50,FALSE) -> [] | T34: =IFERROR(VLOOKUP(TEXT(A34,"0"), inspection_detail_raw!A:BK, 51, FALSE), "알수없음") -> 20261115 | U34: =IFERROR(VLOOKUP(TEXT(A34,"0"), inspection_detail_raw!A:BK, 52, FALSE), "알수없음") -> 20251116 | V34: =IFERROR(VLOOKUP(TEXT(A34,"0"), inspection_detail_raw!A:BK, 54, FALSE), "알수없음") -> KMHR381ADMU24389 | W34: =IFERROR(VLOOKUP(TEXT(A34,"0"), inspection_detail_raw!A:BK, 57, FALSE), "알수없음") -> FALSE | X34: =IFERROR(VLOOKUP(TEXT(A34,"0"), inspection_detail_raw!A:BK, 59, FALSE), "알수없음") -> [] | Y34: =VLOOKUP(A34,vehicle_detail!$A$2:$DK$101,78,FALSE) -> ["10003"] | Z34: =VLOOKUP(A34,vehicle_detail!$A$2:$DK$101,80,FALSE) -> ["001", "004", "005", "006", "007", "008", "014", "015", "017", "019", "020", "021", "022", "023", "024", "026", "027", "030", "031", "032", "033", "034", "051", "055", "056", "057", "058", "059", "062", "063", "072", "074", "075", "077", "079", "081", "082", "084", "085", "086", "087", "088", "090", "094", "096", "097"]
A35: 41393805 | B35: =VLOOKUP(A35,vehicle_detail!$A$2:$DK$101,111,FALSE) -> 14가1316 | C35: =VLOOKUP(A35,vehicle_detail!$A$2:$DK$101,101,FALSE) -> 쥐색 | D35: =VLOOKUP(A35,list_100!$B$2:$P$101,9,FALSE) -> 현대 | E35: =VLOOKUP(A35,list_100!$B$2:$P$101,11,FALSE) -> 아반떼 MD | F35: =VLOOKUP(A35,list_100!$B$2:$P$101,2,FALSE) -> M16 GDI 럭셔리 | G35: =VLOOKUP(A35,list_100!$B$2:$P$101,3,FALSE) -> 0 | H35: =VLOOKUP(A35,list_100!$B$2:$P$101,6,FALSE) -> 2011 | I35: =VLOOKUP(A35,list_100!$B$2:$P$101,7,FALSE) -> 가솔린 | J35: =VLOOKUP(A35,vehicle_detail!$A$2:$DK$101,100,FALSE) -> 준중형차 | K35: =VLOOKUP(A35,list_100!$B$2:$P$101,15,FALSE) -> 370 | L35: =VLOOKUP(A35,list_100!$B$2:$P$101,10,FALSE) -> 155789 | M35: =VLOOKUP(A35,list_100!$B$2:$V$101,21,FALSE) -> 201009 | N35: =VLOOKUP(A35,seller_user!$A$2:$Y$101,2,FALSE) -> qorwogh0827 | O35: =VLOOKUP(A35,seller_user!$A$2:$Y$101,25,FALSE) -> 백재호 | P35: =VLOOKUP(A35,seller_user!$A$2:$Y$101,3,FALSE) -> [{"companyType": "FIRM", "companyName": "위너모터스", "brn": "450-19-00167", "associationCd": 23, "associationName": null, "associationPhoneNumber": null, "certificatedEmployeeNumber": "2500469", "address": {"zipcode": "41752 ", "location": null, "sido": "대구", "sigungu": "서구", "eupmyeondong": null, "eupmyeondongEtc": null, "address": "대구 서구 문화로 37", "buildingCd": "2717010600100420030000001"}, "contacts": null, "used": true}] | Q35: =VLOOKUP(A35,inspection_detail_raw!A35:BK134,4,FALSE) -> ["TABLE"] | R35: =IFERROR("https://ci.encar.com"&VLOOKUP(A35,'성능점검 이미지정보'!A:E,2,FALSE),"") | S35: =VLOOKUP(A35,inspection_detail_raw!A35:BK134,50,FALSE) -> [] | T35: =IFERROR(VLOOKUP(TEXT(A35,"0"), inspection_detail_raw!A:BK, 51, FALSE), "알수없음") -> 20261017 | U35: =IFERROR(VLOOKUP(TEXT(A35,"0"), inspection_detail_raw!A:BK, 52, FALSE), "알수없음") -> 20241018 | V35: =IFERROR(VLOOKUP(TEXT(A35,"0"), inspection_detail_raw!A:BK, 54, FALSE), "알수없음") -> KMHDG41DBBU017175 | W35: =IFERROR(VLOOKUP(TEXT(A35,"0"), inspection_detail_raw!A:BK, 57, FALSE), "알수없음") -> TRUE | X35: =IFERROR(VLOOKUP(TEXT(A35,"0"), inspection_detail_raw!A:BK, 59, FALSE), "알수없음") -> [{"type": {"code": "P062", "title": "쿼터 패널(우)"}, "statusTypes": [{"code": "W", "title": "판금/용접"}], "attributes": ["RANK_TWO"]}, {"type": {"code": "P021", "title": "프론트 휀더(좌)"}, "statusTypes": [{"code": "X", "title": "교환(교체)"}], "attributes": ["RANK_ONE"]}, {"type": {"code": "P061", "title": "쿼터 패널(좌)"}, "statusTypes": [{"code": "W", "title": "판금/용접"}], "attributes": ["RANK_TWO"]}] | Y35: =VLOOKUP(A35,vehicle_detail!$A$2:$DK$101,78,FALSE) -> ["1085", "10001"] | Z35: =VLOOKUP(A35,vehicle_detail!$A$2:$DK$101,80,FALSE) -> ["001", "003", "004", "005", "006", "007", "008", "014", "015", "017", "020", "022", "023", "024", "026", "027", "031", "032", "056", "058", "071", "072", "096", "097"]
A36: 41315606 | B36: =VLOOKUP(A36,vehicle_detail!$A$2:$DK$101,111,FALSE) -> 02구7066 | C36: =VLOOKUP(A36,vehicle_detail!$A$2:$DK$101,101,FALSE) -> 흰색 | D36: =VLOOKUP(A36,list_100!$B$2:$P$101,9,FALSE) -> 현대 | E36: =VLOOKUP(A36,list_100!$B$2:$P$101,11,FALSE) -> 아반떼 AD | F36: =VLOOKUP(A36,list_100!$B$2:$P$101,2,FALSE) -> 1.6 GDI 밸류 플러스 | G36: =VLOOKUP(A36,list_100!$B$2:$P$101,3,FALSE) -> 0 | H36: =VLOOKUP(A36,list_100!$B$2:$P$101,6,FALSE) -> 2018 | I36: =VLOOKUP(A36,list_100!$B$2:$P$101,7,FALSE) -> 가솔린 | J36: =VLOOKUP(A36,vehicle_detail!$A$2:$DK$101,100,FALSE) -> 준중형차 | K36: =VLOOKUP(A36,list_100!$B$2:$P$101,15,FALSE) -> 1210 | L36: =VLOOKUP(A36,list_100!$B$2:$P$101,10,FALSE) -> 53833 | M36: =VLOOKUP(A36,list_100!$B$2:$V$101,21,FALSE) -> 201711 | N36: =VLOOKUP(A36,seller_user!$A$2:$Y$101,2,FALSE) -> thirst1234 | O36: =VLOOKUP(A36,seller_user!$A$2:$Y$101,25,FALSE) -> 이정하 | P36: =VLOOKUP(A36,seller_user!$A$2:$Y$101,3,FALSE) -> [{"companyType": "FIRM", "companyName": "큐모터스", "brn": "596-07-01436", "associationCd": 3, "associationName": "대구 자동차매매사업조합", "associationPhoneNumber": "053-341-7788", "certificatedEmployeeNumber": "20-053-00158", "address": {"zipcode": "41081 ", "location": null, "sido": "대구", "sigungu": "동구", "eupmyeondong": null, "eupmyeondongEtc": null, "address": "대구 동구", "buildingCd": "2714012300103010001033011"}, "contacts": null, "used": true}] | Q36: =VLOOKUP(A36,inspection_detail_raw!A36:BK135,4,FALSE) -> ["TABLE"] | R36: =IFERROR("https://ci.encar.com"&VLOOKUP(A36,'성능점검 이미지정보'!A:E,2,FALSE),"") | S36: =VLOOKUP(A36,inspection_detail_raw!A36:BK135,50,FALSE) -> [] | T36: =IFERROR(VLOOKUP(TEXT(A36,"0"), inspection_detail_raw!A:BK, 51, FALSE), "알수없음") -> 20271031 | U36: =IFERROR(VLOOKUP(TEXT(A36,"0"), inspection_detail_raw!A:BK, 52, FALSE), "알수없음") -> 20251101 | V36: =IFERROR(VLOOKUP(TEXT(A36,"0"), inspection_detail_raw!A:BK, 54, FALSE), "알수없음") -> KMHD641DBJU536296 | W36: =IFERROR(VLOOKUP(TEXT(A36,"0"), inspection_detail_raw!A:BK, 57, FALSE), "알수없음") -> FALSE | X36: =IFERROR(VLOOKUP(TEXT(A36,"0"), inspection_detail_raw!A:BK, 59, FALSE), "알수없음") -> [] | Y36: =VLOOKUP(A36,vehicle_detail!$A$2:$DK$101,78,FALSE) -> ["1009", "1010"] | Z36: =VLOOKUP(A36,vehicle_detail!$A$2:$DK$101,80,FALSE) -> ["001", "004", "005", "006", "007", "008", "014", "015", "017", "019", "020", "022", "024", "026", "027", "031", "032", "033", "055", "056", "057", "058", "071", "072", "074", "086", "096", "097"]
A37: 41313544 | B37: =VLOOKUP(A37,vehicle_detail!$A$2:$DK$101,111,FALSE) -> 380어6657 | C37: =VLOOKUP(A37,vehicle_detail!$A$2:$DK$101,101,FALSE) -> 검정색 | D37: =VLOOKUP(A37,list_100!$B$2:$P$101,9,FALSE) -> 현대 | E37: =VLOOKUP(A37,list_100!$B$2:$P$101,11,FALSE) -> 더 뉴 그랜저 IG | F37: =VLOOKUP(A37,list_100!$B$2:$P$101,2,FALSE) -> 2.5 | G37: =VLOOKUP(A37,list_100!$B$2:$P$101,3,FALSE) -> 르블랑 | H37: =VLOOKUP(A37,list_100!$B$2:$P$101,6,FALSE) -> 2023 | I37: =VLOOKUP(A37,list_100!$B$2:$P$101,7,FALSE) -> 가솔린 | J37: =VLOOKUP(A37,vehicle_detail!$A$2:$DK$101,100,FALSE) -> 대형차 | K37: =VLOOKUP(A37,list_100!$B$2:$P$101,15,FALSE) -> 2590 | L37: =VLOOKUP(A37,list_100!$B$2:$P$101,10,FALSE) -> 70178 | M37: =VLOOKUP(A37,list_100!$B$2:$V$101,21,FALSE) -> 202208 | N37: =VLOOKUP(A37,seller_user!$A$2:$Y$101,2,FALSE) -> lsw30992288 | O37: =VLOOKUP(A37,seller_user!$A$2:$Y$101,25,FALSE) -> T카 용인매매센터 | P37: =VLOOKUP(A37,seller_user!$A$2:$Y$101,3,FALSE) -> [{"companyType": "FIRM", "companyName": "롯데렌탈", "brn": "214-87-79183", "associationCd": 28, "associationName": null, "associationPhoneNumber": null, "certificatedEmployeeNumber": "GC25-03404", "address": {"zipcode": "16994 ", "location": null, "sido": "경기", "sigungu": "용인시", "eupmyeondong": null, "eupmyeondongEtc": null, "address": "경기 용인시 기흥구 어정로 36", "buildingCd": "4146311700106410000000001"}, "contacts": null, "used": true}] | Q37: =VLOOKUP(A37,inspection_detail_raw!A37:BK136,4,FALSE) -> ["TABLE"] | R37: =IFERROR("https://ci.encar.com"&VLOOKUP(A37,'성능점검 이미지정보'!A:E,2,FALSE),"") -> https://ci.encar.com/carsdata/cars/inspection/41313544_photoFront.jpg | S37: =VLOOKUP(A37,inspection_detail_raw!A37:BK136,50,FALSE) -> [{"code": "1", "title": "렌트"}] | T37: =IFERROR(VLOOKUP(TEXT(A37,"0"), inspection_detail_raw!A:BK, 51, FALSE), "알수없음") -> 20260829 | U37: =IFERROR(VLOOKUP(TEXT(A37,"0"), inspection_detail_raw!A:BK, 52, FALSE), "알수없음") -> 20250830 | V37: =IFERROR(VLOOKUP(TEXT(A37,"0"), inspection_detail_raw!A:BK, 54, FALSE), "알수없음") -> KMHF141DBPA515080 | W37: =IFERROR(VLOOKUP(TEXT(A37,"0"), inspection_detail_raw!A:BK, 57, FALSE), "알수없음") -> TRUE | X37: =IFERROR(VLOOKUP(TEXT(A37,"0"), inspection_detail_raw!A:BK, 59, FALSE), "알수없음") -> [{"type": {"code": "P022", "title": "프론트 휀더(우)"}, "statusTypes": [{"code": "W", "title": "판금/용접"}], "attributes": ["RANK_ONE"]}, {"type": {"code": "P011", "title": "후드"}, "statusTypes": [{"code": "X", "title": "교환(교체)"}], "attributes": ["RANK_ONE"]}, {"type": {"code": "P051", "title": "라디에이터 서포트(볼트체결부품)"}, "statusTypes": [{"code": "X", "title": "교환(교체)"}], "attributes": ["RANK_ONE"]}, {"type": {"code": "P021", "title": "프론트 휀더(좌)"}, "statusTypes": [{"code": "W", "title": "판금/용접"}], "attributes": ["RANK_ONE"]}] | Y37: =VLOOKUP(A37,vehicle_detail!$A$2:$DK$101,78,FALSE) -> ["10001"] | Z37: =VLOOKUP(A37,vehicle_detail!$A$2:$DK$101,80,FALSE) -> ["001", "004", "005", "006", "007", "008", "014", "015", "017", "019", "020", "021", "022", "023", "024", "026", "027", "030", "031", "032", "033", "034", "035", "055", "056", "057", "058", "059", "063", "072", "074", "075", "077", "079", "081", "082", "084", "085", "086", "087", "088", "092", "094", "095", "096", "097"]
A38: 41135028 | B38: =VLOOKUP(A38,vehicle_detail!$A$2:$DK$101,111,FALSE) -> 14가8780 | C38: =VLOOKUP(A38,vehicle_detail!$A$2:$DK$101,101,FALSE) -> 은회색 | D38: =VLOOKUP(A38,list_100!$B$2:$P$101,9,FALSE) -> 현대 | E38: =VLOOKUP(A38,list_100!$B$2:$P$101,11,FALSE) -> 아반떼 MD | F38: =VLOOKUP(A38,list_100!$B$2:$P$101,2,FALSE) -> M16 GDI 모던 | G38: =VLOOKUP(A38,list_100!$B$2:$P$101,3,FALSE) -> 0 | H38: =VLOOKUP(A38,list_100!$B$2:$P$101,6,FALSE) -> 2013 | I38: =VLOOKUP(A38,list_100!$B$2:$P$101,7,FALSE) -> 가솔린 | J38: =VLOOKUP(A38,vehicle_detail!$A$2:$DK$101,100,FALSE) -> 준중형차 | K38: =VLOOKUP(A38,list_100!$B$2:$P$101,15,FALSE) -> 450 | L38: =VLOOKUP(A38,list_100!$B$2:$P$101,10,FALSE) -> 128844 | M38: =VLOOKUP(A38,list_100!$B$2:$V$101,21,FALSE) -> 201209 | N38: =VLOOKUP(A38,seller_user!$A$2:$Y$101,2,FALSE) -> skdisk5487 | O38: =VLOOKUP(A38,seller_user!$A$2:$Y$101,25,FALSE) -> 박지안 | P38: =VLOOKUP(A38,seller_user!$A$2:$Y$101,3,FALSE) -> [{"companyType": "FIRM", "companyName": "제이케이 자동차", "brn": "703-86-02533", "associationCd": 7, "associationName": null, "associationPhoneNumber": null, "certificatedEmployeeNumber": "2506200086", "address": {"zipcode": "62071 ", "location": null, "sido": "광주", "sigungu": "서구", "eupmyeondong": null, "eupmyeondongEtc": null, "address": "광주 서구 매월1로62번길 24", "buildingCd": "2914013200106630002000001"}, "contacts": null, "used": true}] | Q38: =VLOOKUP(A38,inspection_detail_raw!A38:BK137,4,FALSE) -> ["TABLE"] | R38: =IFERROR("https://ci.encar.com"&VLOOKUP(A38,'성능점검 이미지정보'!A:E,2,FALSE),"") | S38: =VLOOKUP(A38,inspection_detail_raw!A38:BK137,50,FALSE) -> [] | T38: =IFERROR(VLOOKUP(TEXT(A38,"0"), inspection_detail_raw!A:BK, 51, FALSE), "알수없음") -> 20261128 | U38: =IFERROR(VLOOKUP(TEXT(A38,"0"), inspection_detail_raw!A:BK, 52, FALSE), "알수없음") -> 20241129 | V38: =IFERROR(VLOOKUP(TEXT(A38,"0"), inspection_detail_raw!A:BK, 54, FALSE), "알수없음") -> KMHDH41DBDU645697 | W38: =IFERROR(VLOOKUP(TEXT(A38,"0"), inspection_detail_raw!A:BK, 57, FALSE), "알수없음") -> TRUE | X38: =IFERROR(VLOOKUP(TEXT(A38,"0"), inspection_detail_raw!A:BK, 59, FALSE), "알수없음") -> [{"type": {"code": "P022", "title": "프론트 휀더(우)"}, "statusTypes": [{"code": "X", "title": "교환(교체)"}], "attributes": ["RANK_ONE"]}, {"type": {"code": "P051", "title": "라디에이터 서포트(볼트체결부품)"}, "statusTypes": [{"code": "X", "title": "교환(교체)"}], "attributes": ["RANK_ONE"]}] | Y38: =VLOOKUP(A38,vehicle_detail!$A$2:$DK$101,78,FALSE) -> ["1087", "1103"] | Z38: =VLOOKUP(A38,vehicle_detail!$A$2:$DK$101,80,FALSE) -> ["001", "003", "004", "005", "006", "007", "008", "010", "014", "015", "017", "019", "020", "022", "023", "024", "026", "027", "031", "032", "055", "056", "057", "058", "063", "068", "071", "072", "082", "085", "096", "097"]
